Workbook

Sheet Albero Funzionalità Target
A1: Area Funzionale | B1: Sottoarea | C1: Funzionalità | D1: Stato | E1: Persona principale | F1: Riferimento (dominio ER / Book)
A2: 1. Piattaforma & Multi-tenancy | B2: Gestione Tenant & Organizzazioni | C2: Provisioning e gestione tenant | D2: Esistente | E2: System Admin / Tech Admin
A3: 1. Piattaforma & Multi-tenancy | B3: Gestione Tenant & Organizzazioni | C3: Configurazione e branding per tenant | D3: Esistente | E3: System Admin / Tech Admin
A4: 1. Piattaforma & Multi-tenancy | B4: Gestione Tenant & Organizzazioni | C4: Amministrazione tenant (admin) | D4: Esistente | E4: System Admin / Tech Admin
A5: 1. Piattaforma & Multi-tenancy | B5: Gestione Tenant & Organizzazioni | C5: Gestione organizzazione | D5: Esistente | E5: System Admin / Tech Admin
A6: 1. Piattaforma & Multi-tenancy | B6: Istituzioni & Gerarchia Accademica | C6: Anagrafica Istituzione (estensione del Tenant) | D6: Esistente | E6: System Admin / Tech Admin
A7: 1. Piattaforma & Multi-tenancy | B7: Istituzioni & Gerarchia Accademica | C7: College / School / Department / Program | D7: Esistente | E7: System Admin / Tech Admin
A8: 1. Piattaforma & Multi-tenancy | B8: Istituzioni & Gerarchia Accademica | C8: Workspace di istituzione | D8: Esistente | E8: System Admin / Tech Admin
A9: 1. Piattaforma & Multi-tenancy | B9: Istituzioni & Gerarchia Accademica | C9: Unità accademiche (PI1) | D9: Esistente | E9: System Admin / Tech Admin
A10: 1. Piattaforma & Multi-tenancy | B10: Amministrazione di Piattaforma | C10: Console amministrativa | D10: Esistente | E10: System Admin / Tech Admin
A11: 1. Piattaforma & Multi-tenancy | B11: Amministrazione di Piattaforma | C11: Console operatore (operator plane) | D11: Esistente | E11: System Admin / Tech Admin
A12: 1. Piattaforma & Multi-tenancy | B12: Amministrazione di Piattaforma | C12: Steward console | D12: Esistente | E12: System Admin / Tech Admin
A13: 1. Piattaforma & Multi-tenancy | B13: Amministrazione di Piattaforma | C13: Monitoraggio amministrativo | D13: Esistente | E13: System Admin / Tech Admin
... A16: 1. Piattaforma & Multi-tenancy | B16: Billing & Abbonamenti | C16: Quota e budget crediti | D16: Esistente | E16: System Admin / Tech Admin
A17: 1. Piattaforma & Multi-tenancy | B17: Guardrail & Sicurezza Tenant | C17: Policy guardrail per tenant (egress, data residency, allowlist modelli) | D17: Nuova | E17: System Admin | F17: T12 · BOOK-19 agg.
A18: 1. Piattaforma & Multi-tenancy | B18: Guardrail & Sicurezza Tenant | C18: Audit enforcement guardrail | D18: Nuova | E18: System Admin | F18: T12
A19: 2. Identità, Autenticazione & Accessi | B19: Autenticazione | C19: Registrazione, login, logout (JWT) | D19: Esistente | E19: Tech Admin
A20: 2. Identità, Autenticazione & Accessi | B20: Autenticazione | C20: Gestione e reset password | D20: Esistente | E20: Tech Admin
A21: 2. Identità, Autenticazione & Accessi | B21: Autenticazione | C21: Autenticazione avanzata / sessioni | D21: Esistente | E21: Tech Admin
A22: 2. Identità, Autenticazione & Accessi | B22: Single Sign-On & Federazione | C22: SAML / Shibboleth | D22: Esistente | E22: Tech Admin
A23: 2. Identità, Autenticazione & Accessi | B23: Single Sign-On & Federazione | C23: OIDC | D23: Esistente | E23: Tech Admin
A24: 2. Identità, Autenticazione & Accessi | B24: Single Sign-On & Federazione | C24: Federazione identità | D24: Esistente | E24: Tech Admin
A25: 2. Identità, Autenticazione & Accessi | B25: Single Sign-On & Federazione | C25: LTI 1.3 / piattaforme LTI | D25: Esistente | E25: Tech Admin
A26: 2. Identità, Autenticazione & Accessi | B26: Single Sign-On & Federazione | C26: SPID (via Keycloak) — profilo italiano | D26: Esistente | E26: Tech Admin
A27: 2. Identità, Autenticazione & Accessi | B27: Autorizzazione & Ruoli | C27: RBAC (ruoli e permessi) | D27: Esistente | E27: Tech Admin
A28: 2. Identità, Autenticazione & Accessi | B28: Autorizzazione & Ruoli | C28: Inviti utente | D28: Esistente | E28: Tech Admin
A29: 2. Identità, Autenticazione & Accessi | B29: Autorizzazione & Ruoli | C29: Profilo utente e preferenze | D29: Esistente | E29: Tech Admin
A30: 2. Identità, Autenticazione & Accessi | B30: Autorizzazione & Ruoli | C30: Attivazione / disattivazione utenti | D30: Esistente | E30: Tech Admin
... A47: 3. Authoring & Gestione Corsi | B47: Interscambio Corsi | C47: Import legacy (PPTX/PDF → corso strutturato) | D47: Esistente | E47: Teacher / Dean
A48: 3. Authoring & Gestione Corsi | B48: Ciclo di Vita & Workflow Editoriale | C48: Workflow di approvazione edizione catalogo (Dean→Provost, firma QES) | D48: Nuova | E48: Dean / Provost | F48: T6 · BOOK-24
A49: 3. Authoring & Gestione Corsi | B49: Struttura del Corso | C49: Lineage incarico→corso (authoring engagement) | D49: Nuova | E49: Teacher | F49: T4 · BOOK-22
A50: 4. Generazione AI di Contenuti & Media | B50: Generazione Corsi AI | C50: Course Factory (generazione da syllabus / file) | D50: Esistente | E50: Teacher
A51: 4. Generazione AI di Contenuti & Media | B51: Generazione Corsi AI | C51: Pipeline import legacy (3 fasi con gate di review) | D51: Esistente | E51: Teacher
A52: 4. Generazione AI di Contenuti & Media | B52: Generazione Corsi AI | C52: Architetto del corso / planner legacy→DLU | D52: Esistente | E52: Teacher
A53: 4. Generazione AI di Contenuti & Media | B53: Enrichment Multimediale | C53: Generazione immagini | D53: Esistente | E53: Teacher
A54: 4. Generazione AI di Contenuti & Media | B54: Enrichment Multimediale | C54: Generazione audio / TTS | D54: Esistente | E54: Teacher
A55: 4. Generazione AI di Contenuti & Media | B55: Enrichment Multimediale | C55: Generazione e gestione video | D55: Esistente | E55: Teacher
A56: 4. Generazione AI di Contenuti & Media | B56: Enrichment Multimediale | C56: Avatar Studio / Video Professor (HeyGen) | D56: Esistente | E56: Teacher
A57: 4. Generazione AI di Contenuti & Media | B57: Enrichment Multimediale | C57: Trascrizione | D57: Esistente | E57: Teacher
A58: 4. Generazione AI di Contenuti & Media | B58: Contenuti Interattivi | C58: Generazione quiz | D58: Esistente | E58: Teacher
...

Sheet Riepilogo Aree
A1: Area Funzionale | B1: Totale | C1: Esistenti | D1: Estensioni | E1: Nuove
A2: 1. Piattaforma & Multi-tenancy | B2: =COUNTIF('Albero Funzionalità Target'!$A$2:$A$1000,A2) | C2: =COUNTIFS('Albero Funzionalità Target'!$A$2:$A$1000,A2,'Albero Funzionalità Target'!$D$2:$D$1000,"Esistente") | D2: =COUNTIFS('Albero Funzionalità Target'!$A$2:$A$1000,A2,'Albero Funzionalità Target'!$D$2:$D$1000,"Estensione") | E2: =COUNTIFS('Albero Funzionalità Target'!$A$2:$A$1000,A2,'Albero Funzionalità Target'!$D$2:$D$1000,"Nuova")
A3: 2. Identità, Autenticazione & Accessi | B3: =COUNTIF('Albero Funzionalità Target'!$A$2:$A$1000,A3) | C3: =COUNTIFS('Albero Funzionalità Target'!$A$2:$A$1000,A3,'Albero Funzionalità Target'!$D$2:$D$1000,"Esistente") | D3: =COUNTIFS('Albero Funzionalità Target'!$A$2:$A$1000,A3,'Albero Funzionalità Target'!$D$2:$D$1000,"Estensione") | E3: =COUNTIFS('Albero Funzionalità Target'!$A$2:$A$1000,A3,'Albero Funzionalità Target'!$D$2:$D$1000,"Nuova")
A4: 3. Authoring & Gestione Corsi | B4: =COUNTIF('Albero Funzionalità Target'!$A$2:$A$1000,A4) | C4: =COUNTIFS('Albero Funzionalità Target'!$A$2:$A$1000,A4,'Albero Funzionalità Target'!$D$2:$D$1000,"Esistente") | D4: =COUNTIFS('Albero Funzionalità Target'!$A$2:$A$1000,A4,'Albero Funzionalità Target'!$D$2:$D$1000,"Estensione") | E4: =COUNTIFS('Albero Funzionalità Target'!$A$2:$A$1000,A4,'Albero Funzionalità Target'!$D$2:$D$1000,"Nuova")
A5: 4. Generazione AI di Contenuti & Media | B5: =COUNTIF('Albero Funzionalità Target'!$A$2:$A$1000,A5) | C5: =COUNTIFS('Albero Funzionalità Target'!$A$2:$A$1000,A5,'Albero Funzionalità Target'!$D$2:$D$1000,"Esistente") | D5: =COUNTIFS('Albero Funzionalità Target'!$A$2:$A$1000,A5,'Albero Funzionalità Target'!$D$2:$D$1000,"Estensione") | E5: =COUNTIFS('Albero Funzionalità Target'!$A$2:$A$1000,A5,'Albero Funzionalità Target'!$D$2:$D$1000,"Nuova")
A6: 5. AI Governance & LLM Management | B6: =COUNTIF('Albero Funzionalità Target'!$A$2:$A$1000,A6) | C6: =COUNTIFS('Albero Funzionalità Target'!$A$2:$A$1000,A6,'Albero Funzionalità Target'!$D$2:$D$1000,"Esistente") | D6: =COUNTIFS('Albero Funzionalità Target'!$A$2:$A$1000,A6,'Albero Funzionalità Target'!$D$2:$D$1000,"Estensione") | E6: =COUNTIFS('Albero Funzionalità Target'!$A$2:$A$1000,A6,'Albero Funzionalità Target'!$D$2:$D$1000,"Nuova")
A7: 6. Knowledge Graph & Ontologia | B7: =COUNTIF('Albero Funzionalità Target'!$A$2:$A$1000,A7) | C7: =COUNTIFS('Albero Funzionalità Target'!$A$2:$A$1000,A7,'Albero Funzionalità Target'!$D$2:$D$1000,"Esistente") | D7: =COUNTIFS('Albero Funzionalità Target'!$A$2:$A$1000,A7,'Albero Funzionalità Target'!$D$2:$D$1000,"Estensione") | E7: =COUNTIFS('Albero Funzionalità Target'!$A$2:$A$1000,A7,'Albero Funzionalità Target'!$D$2:$D$1000,"Nuova")
A8: 7. Learning Outcomes & Curriculum | B8: =COUNTIF('Albero Funzionalità Target'!$A$2:$A$1000,A8) | C8: =COUNTIFS('Albero Funzionalità Target'!$A$2:$A$1000,A8,'Albero Funzionalità Target'!$D$2:$D$1000,"Esistente") | D8: =COUNTIFS('Albero Funzionalità Target'!$A$2:$A$1000,A8,'Albero Funzionalità Target'!$D$2:$D$1000,"Estensione") | E8: =COUNTIFS('Albero Funzionalità Target'!$A$2:$A$1000,A8,'Albero Funzionalità Target'!$D$2:$D$1000,"Nuova")
A9: 8. Assessment & Valutazione | B9: =COUNTIF('Albero Funzionalità Target'!$A$2:$A$1000,A9) | C9: =COUNTIFS('Albero Funzionalità Target'!$A$2:$A$1000,A9,'Albero Funzionalità Target'!$D$2:$D$1000,"Esistente") | D9: =COUNTIFS('Albero Funzionalità Target'!$A$2:$A$1000,A9,'Albero Funzionalità Target'!$D$2:$D$1000,"Estensione") | E9: =COUNTIFS('Albero Funzionalità Target'!$A$2:$A$1000,A9,'Albero Funzionalità Target'!$D$2:$D$1000,"Nuova")
A10: 9. Personalizzazione & Apprendimento Adattivo | B10: =COUNTIF('Albero Funzionalità Target'!$A$2:$A$1000,A10) | C10: =COUNTIFS('Albero Funzionalità Target'!$A$2:$A$1000,A10,'Albero Funzionalità Target'!$D$2:$D$1000,"Esistente") | D10: =COUNTIFS('Albero Funzionalità Target'!$A$2:$A$1000,A10,'Albero Funzionalità Target'!$D$2:$D$1000,"Estensione") | E10: =COUNTIFS('Albero Funzionalità Target'!$A$2:$A$1000,A10,'Albero Funzionalità Target'!$D$2:$D$1000,"Nuova")
A11: 10. Esperienza Studente & Lifecycle | B11: =COUNTIF('Albero Funzionalità Target'!$A$2:$A$1000,A11) | C11: =COUNTIFS('Albero Funzionalità Target'!$A$2:$A$1000,A11,'Albero Funzionalità Target'!$D$2:$D$1000,"Esistente") | D11: =COUNTIFS('Albero Funzionalità Target'!$A$2:$A$1000,A11,'Albero Funzionalità Target'!$D$2:$D$1000,"Estensione") | E11: =COUNTIFS('Albero Funzionalità Target'!$A$2:$A$1000,A11,'Albero Funzionalità Target'!$D$2:$D$1000,"Nuova")
A12: 11. Faculty & Staff | B12: =COUNTIF('Albero Funzionalità Target'!$A$2:$A$1000,A12) | C12: =COUNTIFS('Albero Funzionalità Target'!$A$2:$A$1000,A12,'Albero Funzionalità Target'!$D$2:$D$1000,"Esistente") | D12: =COUNTIFS('Albero Funzionalità Target'!$A$2:$A$1000,A12,'Albero Funzionalità Target'!$D$2:$D$1000,"Estensione") | E12: =COUNTIFS('Albero Funzionalità Target'!$A$2:$A$1000,A12,'Albero Funzionalità Target'!$D$2:$D$1000,"Nuova")
A13: 12. Credenziali, Badge & Riconoscimenti | B13: =COUNTIF('Albero Funzionalità Target'!$A$2:$A$1000,A13) | C13: =COUNTIFS('Albero Funzionalità Target'!$A$2:$A$1000,A13,'Albero Funzionalità Target'!$D$2:$D$1000,"Esistente") | D13: =COUNTIFS('Albero Funzionalità Target'!$A$2:$A$1000,A13,'Albero Funzionalità Target'!$D$2:$D$1000,"Estensione") | E13: =COUNTIFS('Albero Funzionalità Target'!$A$2:$A$1000,A13,'Albero Funzionalità Target'!$D$2:$D$1000,"Nuova")
... A27: 26. Accreditamento & Assicurazione Qualità (DM 1154/2021) | B27: =COUNTIF('Albero Funzionalità Target'!$A$2:$A$1000,A27) | C27: =COUNTIFS('Albero Funzionalità Target'!$A$2:$A$1000,A27,'Albero Funzionalità Target'!$D$2:$D$1000,"Esistente") | D27: =COUNTIFS('Albero Funzionalità Target'!$A$2:$A$1000,A27,'Albero Funzionalità Target'!$D$2:$D$1000,"Estensione") | E27: =COUNTIFS('Albero Funzionalità Target'!$A$2:$A$1000,A27,'Albero Funzionalità Target'!$D$2:$D$1000,"Nuova")
A28: TOTALE | B28: =SUM(B2:B27) | C28: =SUM(C2:C27) | D28: =SUM(D2:D27) | E28: =SUM(E2:E27)

Sheet Legenda
A1: Campo | B1: Descrizione
A2: Stato = Esistente | B2: Funzionalità già presente nell MVP dlu_builder_tk (da ALBERO_FUNZIONALITA.xlsx, 27/07/2026)
A3: Stato = Estensione | B3: Funzionalità esistente da estendere per il target (celle gialle)
A4: Stato = Nuova | B4: Funzionalità mancante, da realizzare per il target (celle azzurre)
A5: Persona principale | B5: Per le righe esistenti è un default per area; per le nuove è puntuale
A6: Riferimento | B6: T1–T14 = domini in ER_MAP_TARGET.md · BOOK-xx = volume masterbook (21–26, alcuni in draft)
