Workbook

Sheet Backlog Target
A1: ID | B1: Sprint | C1: Wave | D1: Squad | E1: Sprint cal. | F1: Milestone | G1: Area | H1: Sottoarea | I1: Feature | J1: Tipo | K1: Persona | L1: Rif. ER/Book | M1: Stato avanzamento | N1: Note
A2: BLG-001 | B2: NEW-17a | C2: W1 | D2: A | E2: S2 | F2: M1 | G2: 19. Ammissioni & Pre-Valutazione Titoli | H2: Pre-Valutazione Crediti (dettaglio) | I2: Wizard richiesta con checklist documenti dinamica per percorso (triennale/magistrale/estera/religiosa) | J2: Nuova | K2: Student | L2: PREVAL_SPEC §4 | M2: Da fare
A3: BLG-002 | B3: NEW-17a | C3: W1 | D3: A | E3: S2 | F3: M1 | G3: 19. Ammissioni & Pre-Valutazione Titoli | H3: Pre-Valutazione Crediti (dettaglio) | I3: Coda revisione HITL per confidenza, vista side-by-side, override motivati per riga | J3: Nuova | K3: BackOffice | L3: PREVAL_SPEC A8 | M3: Da fare
A4: BLG-003 | B4: NEW-17a | C4: W1 | D4: A | E4: S2 | F4: M1 | G4: 19. Ammissioni & Pre-Valutazione Titoli | H4: Pre-Valutazione Crediti (dettaglio) | I4: Scheda di pre-valutazione come oggetto dato: composizione, rendering PDF/Word, pubblicazione | J4: Nuova | K4: BackOffice | L4: PREVAL_SPEC A9 | M4: Da fare
A5: BLG-004 | B5: NEW-17a | C5: W1 | D5: A | E5: S2 | F5: M1 | G5: 19. Ammissioni & Pre-Valutazione Titoli | H5: Pre-Valutazione Crediti (dettaglio) | I5: Accettazione e controfirma elettronica dello studente; immutabilità post-firma | J5: Nuova | K5: Student | L5: PREVAL_SPEC §3 | M5: Da fare
A6: BLG-005 | B6: NEW-17b | C6: W1 | D6: B | E6: S2 | F6: M1 | G6: 19. Ammissioni & Pre-Valutazione Titoli | H6: Pre-Valutazione Crediti (dettaglio) | I6: Intake documenti: classificazione, OCR, gate di lavorabilità (identità, anagrafica, dedup/omonimie) | J6: Nuova | K6: Student / BackOffice | L6: PREVAL_SPEC A1 | M6: Da fare
A7: BLG-006 | B7: NEW-17b | C7: W1 | D7: B | E7: S2 | F7: M1 | G7: 19. Ammissioni & Pre-Valutazione Titoli | H7: Pre-Valutazione Crediti (dettaglio) | I7: Parsing transcript: esami, SSD, CFU, voti; rilevazione ordinamento V.O./509/270 | J7: Nuova | K7: BackOffice | L7: PREVAL_SPEC A2 | M7: Da fare
A8: BLG-007 | B8: NEW-17b | C8: W1 | D8: B | E8: S2 | F8: M1 | G8: 19. Ammissioni & Pre-Valutazione Titoli | H8: Pre-Valutazione Crediti (dettaglio) | I8: SSD mapper: SSDiario digitale + crosswalk SSD vecchi→nuovi | J8: Nuova | K8: BackOffice | L8: PREVAL_SPEC A5 | M8: Da fare
A9: BLG-008 | B9: NEW-17b | C9: W1 | D9: B | E9: S2 | F9: M1 | G9: 19. Ammissioni & Pre-Valutazione Titoli | H9: Pre-Valutazione Crediti (dettaglio) | I9: Motore di matching SSD→griglia (precedenze, integrazioni, esuberi, seminario, tirocinio) e calcolo CFU/anno/OFA | J9: Nuova | K9: BackOffice | L9: PREVAL_SPEC A6 | M9: Da fare
A10: BLG-009 | B10: NEW-19 | C10: W1 | D10: A | E10: S3 | F10: M1 | G10: 19. Ammissioni & Pre-Valutazione Titoli | H10: Immatricolazione | I10: Evento ApplicantMatriculated: creazione utente, fascicolo, prima fattura | J10: Nuova | K10: BackOffice | L10: T1/T7/T8 | M10: In corso | N10: Fascicolo + fatture native (T7/T8) esistono ed emissione fattura funziona manualmente (staff); l'evento ApplicantMatriculated stesso NON esiste ancora (prerequisito SPRINT-06) — creazione automatica utente/fascicolo/prima fattura resta da cablare quando quell'evento esisterà.
A11: BLG-010 | B11: NEW-19 | C11: W1 | D11: A | E11: S3 | F11: M1 | G11: 19. Ammissioni & Pre-Valutazione Titoli | H11: Immatricolazione | I11: Verifica identità in immatricolazione (G13) | J11: Estensione | K11: BackOffice | L11: T8 | M11: Fatto | N11: resolve_matriculation_checklist (student_dossier_service.py). Onestamente scoperto ai soli 2 segnali reali: policy configurata + disclosure-ack studente alla versione corrente — nessun evento di verifica-identità-riuscita esiste in questo codebase.
A12: BLG-011 | B12: NEW-19 | C12: W1 | D12: A | E12: S3 | F12: M1 | G12: 22. Finanza & Amministrazione Nativa | H12: Ciclo Attivo (Studenti) | I12: Fatture studente native: emissione, righe, scadenze | J12: Nuova | K12: BackOffice / CFO | L12: T7 · BOOK-23 | M12: Fatto | N12: student_invoices/invoice_lines + finance_service.py (create/issue/mark_overdue), backend/api/routes/invoices.py. C23.1 verificato (property test, Postgres reale).
A13: BLG-012 | B13: NEW-19 | C13: W1 | D13: A | E13: S3 | F13: M1 | G13: 22. Finanza & Amministrazione Nativa | H13: Ciclo Attivo (Studenti) | I13: Riconciliazione pagamenti PagoPA / ERP | J13: Estensione | K13: BackOffice | L13: T7 · pagopa_* | M13: Fatto | N13: payment_reconciliations, finance_service.reconcile_payment (source: pagopa/frappe/manual, idempotente su (source, source_reference)).
A14: BLG-013 | B14: NEW-19 | C14: W1 | D14: A | E14: S3 | F14: M1 | G14: 22. Finanza & Amministrazione Nativa | H14: Ciclo Attivo (Studenti) | I14: Blocchi amministrativi per morosità con effetto su carriera | J14: Estensione | K14: BackOffice | L14: T7 | M14: Fatto | N14: administrative_holds unifica 3 concetti di hold incompatibili (native/stripe/frappe_sync); blocco iscrizione sessione d'esame cablato e verificato (C23.3, stesso boundary transazionale). Gap onesto residuo: blocco credenziali (check_credentials_allowed) non ha ancora un chiamante; trigger automatico overdue→hold non ancora cablato (solo manuale/futuro sweep); GPS non legge ancora administrative_holds come vincolo di percorso.
A15: BLG-014 | B15: NEW-19 | C15: W1 | D15: A | E15: S3 | F15: M1 | G15: 22. Finanza & Amministrazione Nativa | H15: Fascicolo Studente | I15: Fascicolo amministrativo unico per studente | J15: Nuova | K15: BackOffice | L15: T8 · BOOK-23 | M15: Fatto | N15: student_dossiers (1 per twin, UNIQUE), student_dossier_service.get_or_create_dossier.
A16: BLG-015 | B16: NEW-19 | C16: W1 | D16: A | E16: S3 | F16: M1 | G16: 22. Finanza & Amministrazione Nativa | H16: Fascicolo Studente | I16: Checklist immatricolazione e documenti | J16: Nuova | K16: BackOffice | L16: T8 | M16: Fatto | N16: matriculation_checklists (1 riga per voce) + dossier_documents, risolta LIVE da resolve_matriculation_checklist (mai materializzata), stessa disciplina di clearance_service.resolve_clearance_checklist.
A17: BLG-016 | B17: NEW-17c | C17: W1 | D17: B | E17: S3 | F17: M1 | G17: 19. Ammissioni & Pre-Valutazione Titoli | H17: Orientamento | I17: Preview crediti riconoscibili (aggancio pre-valutazione crediti G16) | J17: Estensione | K17: Student | L17: T1 · BOOK-14A | M17: Da fare
A18: BLG-017 | B18: NEW-17c | C18: W1 | D18: B | E18: S3 | F18: M1 | G18: 19. Ammissioni & Pre-Valutazione Titoli | H18: Pre-Valutazione Crediti (dettaglio) | I18: Validazione carriera di provenienza (CINECA/AFAM, pontificie, estere DoV/CIMEA/ARDI, SSML convenzionate) | J18: Nuova | K18: BackOffice | L18: PREVAL_SPEC A3 | M18: Da fare
A19: BLG-018 | B19: NEW-17c | C19: W1 | D19: B | E19: S3 | F19: M1 | G19: 19. Ammissioni & Pre-Valutazione Titoli | H19: Pre-Valutazione Crediti (dettaglio) | I19: Registro certificazioni informatiche/linguistiche valide e non valide | J19: Nuova | K19: BackOffice / Dean | L19: PREVAL_SPEC A4 | M19: Da fare
A20: BLG-019 | B20: NEW-17c | C20: W1 | D20: B | E20: S3 | F20: M1 | G20: 19. Ammissioni & Pre-Valutazione Titoli | H20: Pre-Valutazione Crediti (dettaglio) | I20: Griglie CDS digitalizzate con rule pack di deroghe versionati per a.a. | J20: Nuova | K20: Dean | L20: PREVAL_SPEC A6 | M20: Da fare
A21: BLG-020 | B21: NEW-17c | C21: W1 | D21: B | E21: S3 | F21: M1 | G21: 19. Ammissioni & Pre-Valutazione Titoli | H21: Pre-Valutazione Crediti (dettaglio) | I21: VRA automatico per magistrali (4 esiti, crosswalk classi 509↔270) | J21: Nuova | K21: BackOffice | L21: PREVAL_SPEC A7 | M21: Da fare
A22: BLG-021 | B22: NEW-17c | C22: W1 | D22: B | E22: S3 | F22: M1 | G22: 19. Ammissioni & Pre-Valutazione Titoli | H22: Pre-Valutazione Crediti (dettaglio) | I22: Stima immediata allo studente con banda di confidenza e what-if multi-CDS | J22: Nuova | K22: Student | L22: PREVAL_SPEC §4 | M22: Da fare
A23: BLG-022 | B23: NEW-18 | C23: W1 | D23: A | E23: S4-S5 | F23: M1 | G23: 19. Ammissioni & Pre-Valutazione Titoli | H23: Funnel di Ammissione | I23: Finestre di ammissione (intake) con requisiti per programma | J23: Nuova | K23: BackOffice / Dean | L23: T1 · BOOK-21 | M23: Fatto | N23: admission_intakes + admission_requirements (admission_service.py). Requisiti versionati per intake, immutabili dopo l'apertura (BOOK-21 §3, enforced a livello servizio).
A24: BLG-023 | B24: NEW-18 | C24: W1 | D24: A | E24: S4-S5 | F24: M1 | G24: 19. Ammissioni & Pre-Valutazione Titoli | H24: Funnel di Ammissione | I24: Domanda di ammissione (application) con stato e documenti | J24: Nuova | K24: Student | L24: T1 · BOOK-21 | M24: Fatto | N24: admission_applications, state machine a 11 stati (BOOK-21 §4) + qualification_documents per i documenti allegati.
A25: BLG-024 | B25: NEW-18 | C25: W1 | D25: A | E25: S4-S5 | F25: M1 | G25: 19. Ammissioni & Pre-Valutazione Titoli | H25: Funnel di Ammissione | I25: Conversione lead CRM → application | J25: Nuova | K25: MKO / BackOffice | L25: T1 · crm_* | M25: Fatto | N25: lead_conversion_service.convert_crm_lead_to_application legge CRMLeadMapping direttamente (non tramite crm.py, mai montato). Gap onesto: nessun campo nome/email reale raggiungibile da CRMLeadMapping — applicant_data popolato solo con campi reali (lead_score, sync_status), mai inventato.
A26: BLG-025 | B26: NEW-18 | C26: W1 | D26: A | E26: S4-S5 | F26: M1 | G26: 19. Ammissioni & Pre-Valutazione Titoli | H26: Funnel di Ammissione | I26: Offerta di ammissione, accettazione, scadenze | J26: Nuova | K26: BackOffice | L26: T1 | M26: Fatto | N26: issue_offer (C21.2: richiede verdetto eligible/conditional) + accept_offer/decline_offer/expire_offer, admission_service.py.
A27: BLG-026 | B27: NEW-18 | C27: W1 | D27: A | E27: S4-S5 | F27: M1 | G27: 19. Ammissioni & Pre-Valutazione Titoli | H27: Orientamento | I27: Raccomandazione programma e percorso (GPS pre-iscrizione) | J27: Nuova | K27: Student | L27: T1 · BOOK-14 | M27: In corso | N27: Anteprima crediti riconoscibili reale (riusa preval_workflow_service.compute_instant_estimate, zero-persistenza). La componente GPS/percorso (scenari Pareto multi-obiettivo) NON implementata: il motore GPS richiede un gemello reale, che non esiste pre-immatricolazione — tensione architetturale onestamente disclosurata in BOOK-21 v0.2, non un semplice rinvio.
A28: BLG-027 | B28: NEW-18 | C28: W1 | D28: A | E28: S4-S5 | F28: M1 | G28: 19. Ammissioni & Pre-Valutazione Titoli | H28: Orientamento | I28: Simulazione what-if durata/costo del percorso | J28: Estensione | K28: Student | L28: G15 · BOOK-14 | M28: In corso | N28: ETA: stima standalone semplice (CFU residui / 60 CFU/anno). Costo: placeholder onesto null — nessun campo fee/retta esiste ancora su Program. Nessun confronto multi-scenario Pareto-completo.
A29: BLG-028 | B29: NEW-18 | C29: W1 | D29: A | E29: S4-S5 | F29: M1 | G29: 19. Ammissioni & Pre-Valutazione Titoli | H29: Pre-Valutazione dei Titoli di Studio | I29: Caricamento titoli e documenti (diploma, transcript, ID) | J29: Nuova | K29: Student | L29: T1 | M29: Fatto | N29: qualification_service.add_qualification + add_qualification_document (stessa convenzione document_type/storage_uri di PrevalDocument).
A30: BLG-029 | B30: NEW-18 | C30: W1 | D30: A | E30: S4-S5 | F30: M1 | G30: 19. Ammissioni & Pre-Valutazione Titoli | H30: Pre-Valutazione dei Titoli di Studio | I30: Valutazione AI tier-1 dei titoli (equivalenze, confidenza, DM 931/2024 / PLA) | J30: Nuova | K30: BackOffice | L30: T1 · BOOK-21/14A | M30: Fatto | N30: run_tier1_evaluation. Matching istituzione: euristica onestamente disclosurata (match esatto poi substring case-insensitive su external_courses.source_institution_name) — nessuna vera politica DM 931/2024 codificata, nessun matching fabbricato quando non esiste corrispondenza.
A31: BLG-030 | B31: NEW-18 | C31: W1 | D31: A | E31: S4-S5 | F31: M1 | G31: 19. Ammissioni & Pre-Valutazione Titoli | H31: Pre-Valutazione dei Titoli di Studio | I31: Valutazione assistita / commissione (HITL) | J31: Nuova | K31: Dean / BackOffice | L31: T1 | M31: Fatto | N31: escalate_evaluation_tier (tier 'assisted'/'committee'), motivo obbligatorio non-vuoto (R21.1).
A32: BLG-031 | B32: NEW-18 | C32: W1 | D32: A | E32: S4-S5 | F32: M1 | G32: 19. Ammissioni & Pre-Valutazione Titoli | H32: Pre-Valutazione dei Titoli di Studio | I32: Verdetto di eleggibilità contro i requisiti del programma | J32: Nuova | K32: BackOffice | L32: T1 | M32: Fatto | N32: decide_eligibility + eligibility_verdicts. R21.2 (unmet_requirements obbligatorio per verdetti negativi/condizionati) + R21.3 (admissions_officer+ per verdetto negativo) entrambi verificati con property/fixture test.
A33: BLG-032 | B33: NEW-17d | C33: W1 | D33: B | E33: S4-S5 | F33: M1 | G33: 19. Ammissioni & Pre-Valutazione Titoli | H33: Pre-Valutazione Crediti (dettaglio) | I33: Learning loop: golden set da pratiche storiche, metriche accuracy, GA gate su rilascio regole | J33: Nuova | K33: Admin AI Engineering | L33: PREVAL_SPEC §7 | M33: Fatto | N33: Golden set (preval_eval_builder.py) + metriche (preval_eval_metrics.py: accuracy CFU, precision/recall, escalation/override rate) + learning loop (override HITL -> corretta riga -> golden set aggiornato, chiude anche C21A.6) + gate CI reale (preval_eval_gate.py, blocca build immagine in build-push-images.yml) + report settimanale + config soglia auto-approvazione per-CDS (default OFF, mai attivata). Certificazione onestamente PROVVISORIA: zero dati storici reali in questo ambiente (confermato in pre-flight) — golden set bootstrap (fixture Conti + traffico reale sprint 02-06), non un corpus storico. VRA-exactness e accuracy per componente (estrazione/SSD) onestamente None — nessun ground truth esiste per misurarle.
A34: BLG-033 | B34: NEW-20a | C34: W2 | D34: A | E34: S6 | F34: M2 | G34: 12. Credenziali, Badge & Riconoscimenti | H34: Firma & Export | I34: Contratto esecutivo e edizione catalogo come documenti verificabili | J34: Estensione | K34: Provost / CFO | L34: T4/T6 | M34: Da fare
A35: BLG-034 | B35: NEW-20a | C35: W2 | D35: A | E35: S6 | F35: M2 | G35: 20. Faculty Lifecycle & Contrattualizzazione | H35: Contrattualizzazione Authoring | I35: Generazione contratto da template (corso, formato FEX, compenso) | J35: Nuova | K35: Provost / CFO | L35: T4 | M35: Da fare
A36: BLG-035 | B36: NEW-20a | C36: W2 | D36: A | E36: S6 | F36: M2 | G36: 20. Faculty Lifecycle & Contrattualizzazione | H36: Contrattualizzazione Authoring | I36: Firma digitale multi-ruolo: Provost/CFO/ufficio + docente (QES eIDAS) | J36: Nuova | K36: Provost / CFO / Teacher | L36: T4 · qes_* | M36: Da fare
A37: BLG-036 | B37: NEW-20a | C37: W2 | D37: A | E37: S6 | F37: M2 | G37: 20. Faculty Lifecycle & Contrattualizzazione | H37: Contrattualizzazione Authoring | I37: Archiviazione copia esecutiva come documento verificabile | J37: Nuova | K37: BackOffice | L37: T4 · BOOK-16 | M37: Da fare
A38: BLG-037 | B38: NEW-20a | C38: W2 | D38: A | E38: S6 | F38: M2 | G38: 20. Faculty Lifecycle & Contrattualizzazione | H38: Onboarding Docente | I38: Registrazione docente e creazione account | J38: Nuova | K38: Teacher | L38: T4 · BOOK-22 | M38: Da fare
A39: BLG-038 | B39: NEW-20a | C39: W2 | D39: A | E39: S6 | F39: M2 | G39: 20. Faculty Lifecycle & Contrattualizzazione | H39: Onboarding Docente | I39: Upload documenti: ID personale, career transcript, dati fiscali | J39: Nuova | K39: Teacher | L39: T4 · Course Creation v1.0 | M39: Da fare
A40: BLG-039 | B40: NEW-20a | C40: W2 | D40: A | E40: S6 | F40: M2 | G40: 20. Faculty Lifecycle & Contrattualizzazione | H40: Onboarding Docente | I40: Verifica documenti da back-office e attivazione profilo | J40: Nuova | K40: BackOffice | L40: T4 | M40: Da fare
...

Sheet Riepilogo Sprint
A1: Sprint | B1: Wave | C1: Squad | D1: Sprint cal. | E1: Milestone | F1: Feature totali | G1: Fatte | H1: % completamento
A2: NEW-17f | B2: W0 | C2: A+B | D2: S1 | E2: — | F2: =COUNTIF('Backlog Target'!$B$2:$B$100,A2) | G2: =COUNTIFS('Backlog Target'!$B$2:$B$100,A2,'Backlog Target'!$M$2:$M$100,"Fatto") | H2: =IF(F2=0,"—",G2/F2)
A3: NEW-17a | B3: W1 | C3: A | D3: S2 | E3: M1 | F3: =COUNTIF('Backlog Target'!$B$2:$B$100,A3) | G3: =COUNTIFS('Backlog Target'!$B$2:$B$100,A3,'Backlog Target'!$M$2:$M$100,"Fatto") | H3: =IF(F3=0,"—",G3/F3)
A4: NEW-17b | B4: W1 | C4: B | D4: S2 | E4: M1 | F4: =COUNTIF('Backlog Target'!$B$2:$B$100,A4) | G4: =COUNTIFS('Backlog Target'!$B$2:$B$100,A4,'Backlog Target'!$M$2:$M$100,"Fatto") | H4: =IF(F4=0,"—",G4/F4)
A5: NEW-19 | B5: W1 | C5: A | D5: S3 | E5: M1 | F5: =COUNTIF('Backlog Target'!$B$2:$B$100,A5) | G5: =COUNTIFS('Backlog Target'!$B$2:$B$100,A5,'Backlog Target'!$M$2:$M$100,"Fatto") | H5: =IF(F5=0,"—",G5/F5)
A6: NEW-17c | B6: W1 | C6: B | D6: S3 | E6: M1 | F6: =COUNTIF('Backlog Target'!$B$2:$B$100,A6) | G6: =COUNTIFS('Backlog Target'!$B$2:$B$100,A6,'Backlog Target'!$M$2:$M$100,"Fatto") | H6: =IF(F6=0,"—",G6/F6)
A7: NEW-18 | B7: W1 | C7: A | D7: S4-S5 | E7: M1 | F7: =COUNTIF('Backlog Target'!$B$2:$B$100,A7) | G7: =COUNTIFS('Backlog Target'!$B$2:$B$100,A7,'Backlog Target'!$M$2:$M$100,"Fatto") | H7: =IF(F7=0,"—",G7/F7)
A8: NEW-17d | B8: W1 | C8: B | D8: S4-S5 | E8: M1 | F8: =COUNTIF('Backlog Target'!$B$2:$B$100,A8) | G8: =COUNTIFS('Backlog Target'!$B$2:$B$100,A8,'Backlog Target'!$M$2:$M$100,"Fatto") | H8: =IF(F8=0,"—",G8/F8)
A9: NEW-20a | B9: W2 | C9: A | D9: S6 | E9: M2 | F9: =COUNTIF('Backlog Target'!$B$2:$B$100,A9) | G9: =COUNTIFS('Backlog Target'!$B$2:$B$100,A9,'Backlog Target'!$M$2:$M$100,"Fatto") | H9: =IF(F9=0,"—",G9/F9)
A10: NEW-22 | B10: W2 | C10: B | D10: S6 | E10: M2 | F10: =COUNTIF('Backlog Target'!$B$2:$B$100,A10) | G10: =COUNTIFS('Backlog Target'!$B$2:$B$100,A10,'Backlog Target'!$M$2:$M$100,"Fatto") | H10: =IF(F10=0,"—",G10/F10)
A11: NEW-20b | B11: W2 | C11: A | D11: S7 | E11: M2 | F11: =COUNTIF('Backlog Target'!$B$2:$B$100,A11) | G11: =COUNTIFS('Backlog Target'!$B$2:$B$100,A11,'Backlog Target'!$M$2:$M$100,"Fatto") | H11: =IF(F11=0,"—",G11/F11)
A12: NEW-23 | B12: W2 | C12: B | D12: S7 | E12: M2 | F12: =COUNTIF('Backlog Target'!$B$2:$B$100,A12) | G12: =COUNTIFS('Backlog Target'!$B$2:$B$100,A12,'Backlog Target'!$M$2:$M$100,"Fatto") | H12: =IF(F12=0,"—",G12/F12)
A13: NEW-21 | B13: W2 | C13: A | D13: S8 | E13: M2 | F13: =COUNTIF('Backlog Target'!$B$2:$B$100,A13) | G13: =COUNTIFS('Backlog Target'!$B$2:$B$100,A13,'Backlog Target'!$M$2:$M$100,"Fatto") | H13: =IF(F13=0,"—",G13/F13)
... A23: NEW-29 | B23: W4 | C23: A+B | D23: S22c | E23: M3 | F23: =COUNTIF('Backlog Target'!$B$2:$B$100,A23) | G23: =COUNTIFS('Backlog Target'!$B$2:$B$100,A23,'Backlog Target'!$M$2:$M$100,"Fatto") | H23: =IF(F23=0,"—",G23/F23)
A24: AVA-01 | B24: W5 | C24: A+B | D24: — | E24: M4 | F24: =COUNTIF('Backlog Target'!$B$2:$B$200,A24) | G24: =COUNTIFS('Backlog Target'!$B$2:$B$200,A24,'Backlog Target'!$M$2:$M$200,"Fatto") | H24: =IF(F24=0,"—",G24/F24)
A25: AVA-02 | B25: W5 | C25: A+B | D25: S23 | E25: M4 | F25: =COUNTIF('Backlog Target'!$B$2:$B$200,A25) | G25: =COUNTIFS('Backlog Target'!$B$2:$B$200,A25,'Backlog Target'!$M$2:$M$200,"Fatto") | H25: =IF(F25=0,"—",G25/F25)
A26: AVA-03 | B26: W5 | C26: A+B | D26: S23 | E26: M4 | F26: =COUNTIF('Backlog Target'!$B$2:$B$200,A26) | G26: =COUNTIFS('Backlog Target'!$B$2:$B$200,A26,'Backlog Target'!$M$2:$M$200,"Fatto") | H26: =IF(F26=0,"—",G26/F26)
A27: AVA-04 | B27: W5 | C27: A+B | D27: S23 | E27: M4 | F27: =COUNTIF('Backlog Target'!$B$2:$B$200,A27) | G27: =COUNTIFS('Backlog Target'!$B$2:$B$200,A27,'Backlog Target'!$M$2:$M$200,"Fatto") | H27: =IF(F27=0,"—",G27/F27)
A28: AVA-05 | B28: W5 | C28: A+B | D28: S24 | E28: M4 | F28: =COUNTIF('Backlog Target'!$B$2:$B$200,A28) | G28: =COUNTIFS('Backlog Target'!$B$2:$B$200,A28,'Backlog Target'!$M$2:$M$200,"Fatto") | H28: =IF(F28=0,"—",G28/F28)
A29: AVA-06 | B29: W5 | C29: A+B | D29: S24 | E29: M4 | F29: =COUNTIF('Backlog Target'!$B$2:$B$200,A29) | G29: =COUNTIFS('Backlog Target'!$B$2:$B$200,A29,'Backlog Target'!$M$2:$M$200,"Fatto") | H29: =IF(F29=0,"—",G29/F29)
A30: AVA-07 | B30: W5 | C30: A+B | D30: S24 | E30: M4 | F30: =COUNTIF('Backlog Target'!$B$2:$B$200,A30) | G30: =COUNTIFS('Backlog Target'!$B$2:$B$200,A30,'Backlog Target'!$M$2:$M$200,"Fatto") | H30: =IF(F30=0,"—",G30/F30)
A31: AVA-08 | B31: W5 | C31: A+B | D31: S25 | E31: M4 | F31: =COUNTIF('Backlog Target'!$B$2:$B$200,A31) | G31: =COUNTIFS('Backlog Target'!$B$2:$B$200,A31,'Backlog Target'!$M$2:$M$200,"Fatto") | H31: =IF(F31=0,"—",G31/F31)
A32: AVA-09 | B32: W5 | C32: A+B | D32: S25 | E32: M4 | F32: =COUNTIF('Backlog Target'!$B$2:$B$200,A32) | G32: =COUNTIFS('Backlog Target'!$B$2:$B$200,A32,'Backlog Target'!$M$2:$M$200,"Fatto") | H32: =IF(F32=0,"—",G32/F32)
A33: AVA-10 | B33: W5 | C33: A+B | D33: S25 | E33: M4 | F33: =COUNTIF('Backlog Target'!$B$2:$B$200,A33) | G33: =COUNTIFS('Backlog Target'!$B$2:$B$200,A33,'Backlog Target'!$M$2:$M$200,"Fatto") | H33: =IF(F33=0,"—",G33/F33)
A34: AVA-11 | B34: W5 | C34: A+B | D34: S25 | E34: M4 | F34: =COUNTIF('Backlog Target'!$B$2:$B$200,A34) | G34: =COUNTIFS('Backlog Target'!$B$2:$B$200,A34,'Backlog Target'!$M$2:$M$200,"Fatto") | H34: =IF(F34=0,"—",G34/F34)
A35: AVA-12 | B35: W5 | C35: A+B | D35: S25 | E35: M4 | F35: =COUNTIF('Backlog Target'!$B$2:$B$200,A35) | G35: =COUNTIFS('Backlog Target'!$B$2:$B$200,A35,'Backlog Target'!$M$2:$M$200,"Fatto") | H35: =IF(F35=0,"—",G35/F35)
A36: TOTALE | F36: =SUM(F2:F35) | G36: =SUM(G2:G35) | H36: =IF(F36=0,0,G36/F36)

Sheet Legenda
A1: Campo | B1: Descrizione
A2: ID | B2: BLG-nnn, ordinato per sequenza di piano (sprint → area)
A3: Sprint | B3: Card NEW-xx del PIANO_SPRINT_TARGET.md (numerazione registro masterbook) o AVA-xx (programma DM 1154/2021, TRACEABILITY.md G22, fuori dal piano NEW-xx originale)
A4: Wave / Squad / Sprint cal. | B4: Ondata W0–W4 (piano NEW-xx originale) + W5 (programma AVA, post-piano) · squad A (Platform) / B (AI & Product) / A+B · sprint di calendario S1–S22c (piano originale), S23–S25 (AVA, disclosed placement — nessun piano preesistente assegnava AVA a un'ondata/sprint-cal.)
A5: Milestone | B5: M1 PreEval+Intake (fine nov 2026) · M2 Faculty+Student loop (fine dic 2026) · M3 target completo (metà feb 2027) · M4 Accreditamento & QA — DM 1154/2021 (fuori scope piano originale, aggiunta AVA)
A6: Tipo | B6: Nuova (90 = 75 piano originale + 15 AVA) o Estensione (7) — da ALBERO_FUNZIONALITA_TARGET.xlsx
A7: Stato avanzamento | B7: Da fare / In corso / In review / Fatto / Bloccato (tendina) — unico campo da aggiornare
A8: Nota metodo | B8: NEW-17f (fondazioni) e NEW-29 includono anche lavoro non-feature (migrazioni, taxonomy, conformance): qui compaiono solo le feature dell albero. AVA-01 (schema-only) segue la stessa convenzione — zero righe qui, coerente con zero righe proprie nell'Albero.
